<robot name="GEN3_URDF_V12" version="1.0">
  <link name="World">
  </link>
  <link name="Base_Link">
    <inertial>
      <origin xyz="-0.000648 -0.000166 0.084487" rpy="0 0 0" />
      <mass value="1.697" />
      <inertia ixx="0.004622" ixy="9E-06" ixz="6E-05" iyy="0.004495" iyz="9E-06" izz="0.002079" />
    </inertial>
    <visual>
      <origin xyz="0 0 0" rpy="0 0 0" />
      <geometry>
        <mesh filename="package://home/zjd/arm/src/iserve_controller/config/urdf/kinova_gen3_7dof/meshes/base_link.STL" />
      </geometry>
      <material name="">
        <color rgba="0.75294 0.75294 0.75294 1" />
      </material>
    </visual>
    <collision>
      <origin xyz="0 0 0" rpy="0 0 0" />
      <geometry>
        <mesh filename="package://home/zjd/arm/src/iserve_controller/config/urdf/kinova_gen3_7dof/meshes/base_link.STL" />
      </geometry>
    </collision>
  </link>
  <joint name="Connect_Base_to_World" type="fixed">
    <origin xyz="0 0 0" rpy="0 0 0"/>
    <parent link="World"/>
    <child link="Base_Link"/> 
  </joint>
  <link name="Shoulder_Link">
    <inertial>
      <origin xyz="-2.3E-05 -0.010364 -0.07336" rpy="0 0 0" />
      <mass value="1.3773" />
      <inertia ixx="0.00457" ixy="1E-06" ixz="2E-06" iyy="0.004831" iyz="0.000448" izz="0.001409" />
    </inertial>
    <visual>
      <origin xyz="0 0 0" rpy="0 0 0" />
      <geometry>
        <mesh filename="package://home/zjd/arm/src/iserve_controller/config/urdf/kinova_gen3_7dof/meshes/shoulder_link.STL" />
      </geometry>
      <material name="">
        <color rgba="0.75294 0.75294 0.75294 1" />
      </material>
    </visual>
    <collision>
      <origin xyz="0 0 0" rpy="0 0 0" />
      <geometry>
        <mesh filename="package://home/zjd/arm/src/iserve_controller/config/urdf/kinova_gen3_7dof/meshes/shoulder_link.STL" />
      </geometry>
    </collision>
  </link>
  <joint name="Actuator1" type="continuous">
    <origin xyz="0.0055 -0.15535 0.42999" rpy="-0.43633 0 0" />
    <parent link="Base_Link" />
    <child link="Shoulder_Link" />
    <axis xyz="0 1 0" />
    <limit lower="-2.87" upper="2.87" effort="40" velocity="9" />
  </joint>
  <link name="HalfArm1_Link">
    <inertial>
      <origin xyz="-4.4E-05 -0.09958 -0.013278" rpy="0 0 0" />
      <mass value="1.1636" />
      <inertia ixx="0.011088" ixy="5E-06" ixz="0" iyy="0.001072" iyz="-0.000691" izz="0.011255" />
    </inertial>
    <visual>
      <origin xyz="0 0 0" rpy="0 0 0" />
      <geometry>
        <mesh filename="package://home/zjd/arm/src/iserve_controller/config/urdf/kinova_gen3_7dof/meshes/half_arm_1_link.STL" />
      </geometry>
      <material name="">
        <color rgba="0.75294 0.75294 0.75294 1" />
      </material>
    </visual>
    <collision>
      <origin xyz="0 0 0" rpy="0 0 0" />
      <geometry>
        <mesh filename="package://home/zjd/arm/src/iserve_controller/config/urdf/kinova_gen3_7dof/meshes/half_arm_1_link.STL" />
      </geometry>
    </collision>
  </link>
  <joint name="Actuator2" type="revolute">
    <origin xyz="-0.0055 -0.0565 -0.0165" rpy="0.43633 0 0" />
    <parent link="Shoulder_Link" />
    <child link="HalfArm1_Link" />
    <axis xyz="1 0 0" />
    <limit lower="-3.11" upper="0.34" effort="40" velocity="9" />
  </joint>
  <link name="HalfArm2_Link">
    <inertial>
      <origin xyz="-4.4E-05 -0.006641 -0.117892" rpy="0 0 0" />
      <mass value="1.1636" />
      <inertia ixx="0.010932" ixy="0" ixz="-7E-06" iyy="0.011127" iyz="0.000606" izz="0.001043" />
    </inertial>
    <visual>
      <origin xyz="0 0 0" rpy="0 0 0" />
      <geometry>
        <mesh filename="package://home/zjd/arm/src/iserve_controller/config/urdf/kinova_gen3_7dof/meshes/half_arm_2_link.STL" />
      </geometry>
      <material name="">
        <color rgba="0.75294 0.75294 0.75294 1" />
      </material>
    </visual>
    <collision>
      <origin xyz="0 0 0" rpy="0 0 0" />
      <geometry>
        <mesh filename="package://home/zjd/arm/src/iserve_controller/config/urdf/kinova_gen3_7dof/meshes/half_arm_2_link.STL" />
      </geometry>
    </collision>
  </link>
  <joint name="Actuator3" type="continuous">
    <origin xyz="0 0 -0.1343" rpy="0 0 0" />
    <parent link="HalfArm1_Link" />
    <child link="HalfArm2_Link" />
    <axis xyz="0 0 1" />
    <limit lower="-4.45" upper="1.3" effort="18" velocity="20" />
  </joint>
  <link name="ForeArm_Link">
    <inertial>
      <origin xyz="-1.8E-05 -0.075478 -0.015006" rpy="0 0 0" />
      <mass value="0.9302" />
      <inertia ixx="0.008147" ixy="-1E-06" ixz="0" iyy="0.000631" iyz="-0.0005" izz="0.008316" />
    </inertial>
    <visual>
      <origin xyz="0 0 0" rpy="0 0 0" />
      <geometry>
        <mesh filename="package://home/zjd/arm/src/iserve_controller/config/urdf/kinova_gen3_7dof/meshes/forearm_link.STL" />
      </geometry>
      <material name="">
        <color rgba="0.75294 0.75294 0.75294 1" />
      </material>
    </visual>
    <collision>
      <origin xyz="0 0 0" rpy="0 0 0" />
      <geometry>
        <mesh filename="package://home/zjd/arm/src/iserve_controller/config/urdf/kinova_gen3_7dof/meshes/forearm_link.STL" />
      </geometry>
    </collision>
  </link>
  <joint name="Actuator4" type="revolute">
    <origin xyz="0.0185 0 -0.198" rpy="0 0 0" />
    <parent link="HalfArm2_Link" />
    <child link="ForeArm_Link" />
    <axis xyz="0 1 0" />
    <limit lower="-1.25" upper="2.61" effort="18" velocity="20" />
  </joint>
  <link name="EndEffector_Link" />
  <joint name="EndEffector" type="continuous">
    <origin xyz="0.2605 0 -0.0185" rpy="0 0 0" />
    <parent link="ForeArm_Link" />
    <child link="EndEffector_Link" />
    <axis xyz="0 0 0" />
  </joint>
</robot>
